2024-12-26 18:52:30,051 - Нет валидных ордеров после обработки. Исходные данные: {'e': 'depthUpdate', 'E': 1735231950807, 'T': 1735231950758, 's': 'STRKUSDT', 'U': 6249656254095, 'u': 6249656258279, 'pu': 6249656244569, 'b': [], 'a': [['0.4700000', '15261.5'], ['0.4702000', '14952.9'], ['0.4703000', '14126.9'], ['0.5229000', '2912.7'], ['0.5297000', '18.8']]}
2024-12-26 18:52:30,369 - Нет валидных ордеров после обработки. Исходные данные: {'e': 'depthUpdate', 'E': 1735231951128, 'T': 1735231951080, 's': 'STRKUSDT', 'U': 6249656273923, 'u': 6249656278039, 'pu': 6249656258279, 'b': [['0.3760000', '497.1']], 'a': []}
2024-12-26 18:52:30,669 - Нет валидных ордеров после обработки. Исходные данные: {'e': 'depthUpdate', 'E': 1735231951426, 'T': 1735231951425, 's': 'STRKUSDT', 'U': 6249656302236, 'u': 6249656324196, 'pu': 6249656296624, 'b': [['0.4489000', '20.7'], ['0.4692000', '60604.4'], ['0.4693000', '55305.4'], ['0.4698000', '9501.4']], 'a': []}
2024-12-26 18:52:30,774 - Нет валидных ордеров после обработки. Исходные данные: {'e': 'depthUpdate', 'E': 1735231951533, 'T': 1735231951439, 's': 'STRKUSDT', 'U': 6249656325441, 'u': 6249656326714, 'pu': 6249656324196, 'b': [], 'a': [['0.4705000', '29733.5'], ['0.4706000', '27433.4']]}
2024-12-26 18:52:31,041 - Нет валидных ордеров после обработки. Исходные данные: {'e': 'depthUpdate', 'E': 1735231951799, 'T': 1735231951698, 's': 'STRKUSDT', 'U': 6249656378692, 'u': 6249656378692, 'pu': 6249656372738, 'b': [['0.4488000', '35672.0']], 'a': []}
2024-12-26 18:52:31,186 - Нет валидных ордеров после обработки. Исходные данные: {'e': 'depthUpdate', 'E': 1735231951944, 'T': 1735231951846, 's': 'STRKUSDT', 'U': 6249656394157, 'u': 6249656394612, 'pu': 6249656378692, 'b': [['0.4684000', '46670.7'], ['0.4692000', '59538.1'], ['0.4693000', '56371.7']], 'a': []}
2024-12-26 18:52:31,424 - Нет валидных ордеров после обработки. Исходные данные: {'e': 'depthUpdate', 'E': 1735231952179, 'T': 1735231952138, 's': 'STRKUSDT', 'U': 6249656410433, 'u': 6249656417309, 'pu': 6249656394612, 'b': [['0.3760000', '656.6'], ['0.4695000', '24756.7'], ['0.4696000', '26537.1'], ['0.4697000', '14761.0'], ['0.4698000', '6228.9']], 'a': []}
2024-12-26 18:52:31,524 - Нет валидных ордеров после обработки. Исходные данные: {'e': 'depthUpdate', 'E': 1735231952282, 'T': 1735231952243, 's': 'STRKUSDT', 'U': 6249656419955, 'u': 6249656427584, 'pu': 6249656417309, 'b': [['0.3760000', '497.1'], ['0.4692000', '60604.4'], ['0.4693000', '55305.4']], 'a': []}
2024-12-26 18:52:31,870 - Нет валидных ордеров после обработки. Исходные данные: {'e': 'depthUpdate', 'E': 1735231952630, 'T': 1735231952568, 's': 'STRKUSDT', 'U': 6249656449643, 'u': 6249656452105, 'pu': 6249656445711, 'b': [['0.4692000', '60604.4'], ['0.4693000', '55305.4'], ['0.4695000', '25311.2']], 'a': []}
2024-12-26 18:52:32,991 - Нет валидных ордеров после обработки. Исходные данные: {'e': 'depthUpdate', 'E': 1735231953750, 'T': 1735231953649, 's': 'STRKUSDT', 'U': 6249656550962, 'u': 6249656550962, 'pu': 6249656550678, 'b': [['0.3760000', '497.1']], 'a': []}
2024-12-26 18:52:33,332 - Нет валидных ордеров после обработки. Исходные данные: {'e': 'depthUpdate', 'E': 1735231954091, 'T': 1735231954039, 's': 'STRKUSDT', 'U': 6249656571077, 'u': 6249656583828, 'pu': 6249656550962, 'b': [], 'a': [['0.4705000', '25231.4'], ['0.4706000', '26369.8'], ['0.4730000', '16419.2']]}
2024-12-26 18:52:33,455 - Нет валидных ордеров после обработки. Исходные данные: {'e': 'depthUpdate', 'E': 1735231954215, 'T': 1735231954188, 's': 'STRKUSDT', 'U': 6249656596029, 'u': 6249656617172, 'pu': 6249656583828, 'b': [['0.3760000', '497.1']], 'a': []}
2024-12-26 18:52:35,411 - Нет валидных ордеров после обработки. Исходные данные: {'e': 'depthUpdate', 'E': 1735231956169, 'T': 1735231956081, 's': 'STRKUSDT', 'U': 6249656967191, 'u': 6249656968230, 'pu': 6249656957264, 'b': [['0.4697000', '710.1']], 'a': []}
2024-12-26 18:52:35,761 - Нет валидных ордеров после обработки. Исходные данные: {'e': 'depthUpdate', 'E': 1735231956515, 'T': 1735231956414, 's': 'STRKUSDT', 'U': 6249656988414, 'u': 6249656988414, 'pu': 6249656987005, 'b': [['0.4697000', '710.1']], 'a': []}
2024-12-26 18:52:36,094 - Нет валидных ордеров после обработки. Исходные данные: {'e': 'depthUpdate', 'E': 1735231956853, 'T': 1735231956752, 's': 'STRKUSDT', 'U': 6249657003217, 'u': 6249657003217, 'pu': 6249656988414, 'b': [], 'a': [['0.5052000', '0.0']]}
2024-12-26 18:52:36,196 - Нет валидных ордеров после обработки. Исходные данные: {'e': 'depthUpdate', 'E': 1735231956956, 'T': 1735231956905, 's': 'STRKUSDT', 'U': 6249657008208, 'u': 6249657010938, 'pu': 6249657003217, 'b': [['0.3758000', '1412.5']], 'a': []}
2024-12-26 18:52:36,799 - Нет валидных ордеров после обработки. Исходные данные: {'e': 'depthUpdate', 'E': 1735231957557, 'T': 1735231957455, 's': 'STRKUSDT', 'U': 6249657092084, 'u': 6249657092084, 'pu': 6249657084352, 'b': [['0.3758000', '1412.5']], 'a': []}
2024-12-26 18:52:37,124 - Нет валидных ордеров после обработки. Исходные данные: {'e': 'depthUpdate', 'E': 1735231957882, 'T': 1735231957781, 's': 'STRKUSDT', 'U': 6249657155415, 'u': 6249657155415, 'pu': 6249657131448, 'b': [], 'a': [['0.4703000', '29345.8'], ['0.4704000', '25721.9']]}
2024-12-26 18:52:37,275 - Нет валидных ордеров после обработки. Исходные данные: {'e': 'depthUpdate', 'E': 1735231958033, 'T': 1735231957985, 's': 'STRKUSDT', 'U': 6249657170814, 'u': 6249657174265, 'pu': 6249657155415, 'b': [['0.3758000', '1412.5']], 'a': []}
2024-12-26 18:52:37,483 - Нет валидных ордеров после обработки. Исходные данные: {'e': 'depthUpdate', 'E': 1735231958242, 'T': 1735231958141, 's': 'STRKUSDT', 'U': 6249657183852, 'u': 6249657183852, 'pu': 6249657174265, 'b': [['0.4697000', '35.2']], 'a': []}
2024-12-26 18:52:38,056 - Нет валидных ордеров после обработки. Исходные данные: {'e': 'depthUpdate', 'E': 1735231958815, 'T': 1735231958814, 's': 'STRKUSDT', 'U': 6249657213944, 'u': 6249657223735, 'pu': 6249657210443, 'b': [['0.4688000', '37298.8'], ['0.4689000', '25636.1'], ['0.4691000', '50552.2'], ['0.4692000', '57536.1'], ['0.4693000', '38298.0'], ['0.4694000', '24145.1'], ['0.4695000', '12988.6']], 'a': []}
2024-12-26 18:52:38,378 - Нет валидных ордеров после обработки. Исходные данные: {'e': 'depthUpdate', 'E': 1735231959137, 'T': 1735231959047, 's': 'STRKUSDT', 'U': 6249657261085, 'u': 6249657262042, 'pu': 6249657253512, 'b': [['0.3758000', '1412.5'], ['0.4682000', '29416.0']], 'a': []}
2024-12-26 18:52:38,530 - Нет валидных ордеров после обработки. Исходные данные: {'e': 'depthUpdate', 'E': 1735231959288, 'T': 1735231959271, 's': 'STRKUSDT', 'U': 6249657273379, 'u': 6249657279762, 'pu': 6249657262042, 'b': [['0.4690000', '39519.1'], ['0.4693000', '38323.7'], ['0.4694000', '23745.1'], ['0.4697000', '181.0']], 'a': []}
2024-12-26 18:52:38,848 - Нет валидных ордеров после обработки. Исходные данные: {'e': 'depthUpdate', 'E': 1735231959602, 'T': 1735231959595, 's': 'STRKUSDT', 'U': 6249657296986, 'u': 6249657305567, 'pu': 6249657279762, 'b': [['0.3758000', '1412.5'], ['0.4694000', '23945.1'], ['0.4695000', '12788.6'], ['0.4697000', '35.2']], 'a': []}
2024-12-26 18:52:38,979 - Нет валидных ордеров после обработки. Исходные данные: {'e': 'depthUpdate', 'E': 1735231959738, 'T': 1735231959637, 's': 'STRKUSDT', 'U': 6249657311076, 'u': 6249657311076, 'pu': 6249657305567, 'b': [['0.4696000', '6117.5']], 'a': []}
2024-12-26 18:52:39,413 - Нет валидных ордеров после обработки. Исходные данные: {'e': 'depthUpdate', 'E': 1735231960172, 'T': 1735231960127, 's': 'STRKUSDT', 'U': 6249657343373, 'u': 6249657348525, 'pu': 6249657311076, 'b': [['0.3758000', '1412.5'], ['0.4693000', '38323.7'], ['0.4694000', '23945.1'], ['0.4697000', '45.9']], 'a': []}
2024-12-26 18:52:40,581 - Нет валидных ордеров после обработки. Исходные данные: {'e': 'depthUpdate', 'E': 1735231961340, 'T': 1735231961308, 's': 'STRKUSDT', 'U': 6249657454370, 'u': 6249657459840, 'pu': 6249657454127, 'b': [['0.3758000', '1412.5'], ['0.4686000', '29250.1'], ['0.4697000', '468.7']], 'a': []}
2024-12-26 18:52:40,691 - Нет валидных ордеров после обработки. Исходные данные: {'e': 'depthUpdate', 'E': 1735231961450, 'T': 1735231961348, 's': 'STRKUSDT', 'U': 6249657462548, 'u': 6249657462548, 'pu': 6249657459840, 'b': [['0.4697000', '473.0']], 'a': []}
2024-12-26 18:52:41,070 - Нет валидных ордеров после обработки. Исходные данные: {'e': 'depthUpdate', 'E': 1735231961828, 'T': 1735231961805, 's': 'STRKUSDT', 'U': 6249657485369, 'u': 6249657489931, 'pu': 6249657478408, 'b': [['0.3758000', '1412.5'], ['0.4685000', '12218.2'], ['0.4687000', '48725.1']], 'a': []}
2024-12-26 18:52:41,291 - Нет валидных ордеров после обработки. Исходные данные: {'e': 'depthUpdate', 'E': 1735231962048, 'T': 1735231962002, 's': 'STRKUSDT', 'U': 6249657498067, 'u': 6249657501173, 'pu': 6249657489931, 'b': [['0.4654000', '38410.1'], ['0.4669000', '54371.3'], ['0.4693000', '38323.7'], ['0.4694000', '26818.9'], ['0.4695000', '12788.6']], 'a': []}
2024-12-26 18:52:42,049 - Нет валидных ордеров после обработки. Исходные данные: {'e': 'depthUpdate', 'E': 1735231962807, 'T': 1735231962720, 's': 'STRKUSDT', 'U': 6249657758568, 'u': 6249657759894, 'pu': 6249657757312, 'b': [], 'a': [['0.4941000', '99.0'], ['0.4959000', '3348.5'], ['0.5199000', '90.4'], ['0.5307000', '2844.3']]}
2024-12-26 18:52:42,204 - Нет валидных ордеров после обработки. Исходные данные: {'e': 'depthUpdate', 'E': 1735231962962, 'T': 1735231962861, 's': 'STRKUSDT', 'U': 6249657775979, 'u': 6249657775979, 'pu': 6249657759894, 'b': [], 'a': [['0.4715000', '52903.9']]}
2024-12-26 18:52:42,479 - Нет валидных ордеров после обработки. Исходные данные: {'e': 'depthUpdate', 'E': 1735231963236, 'T': 1735231963134, 's': 'STRKUSDT', 'U': 6249657806412, 'u': 6249657806412, 'pu': 6249657800112, 'b': [['0.3760000', '497.1']], 'a': []}
2024-12-26 18:52:42,659 - Нет валидных ордеров после обработки. Исходные данные: {'e': 'depthUpdate', 'E': 1735231963417, 'T': 1735231963387, 's': 'STRKUSDT', 'U': 6249657826801, 'u': 6249657833717, 'pu': 6249657806412, 'b': [['0.4686000', '29812.1'], ['0.4687000', '44014.8'], ['0.4688000', '32419.1'], ['0.4690000', '15917.5'], ['0.4693000', '56523.9'], ['0.4698000', '19854.1'], ['0.4699000', '16614.8']], 'a': []}
2024-12-26 18:52:42,792 - Нет валидных ордеров после обработки. Исходные данные: {'e': 'depthUpdate', 'E': 1735231963552, 'T': 1735231963529, 's': 'STRKUSDT', 'U': 6249657840837, 'u': 6249657849970, 'pu': 6249657833717, 'b': [['0.4601000', '344.3'], ['0.4695000', '17091.3']], 'a': []}
2024-12-26 18:52:42,927 - Нет валидных ордеров после обработки. Исходные данные: {'e': 'depthUpdate', 'E': 1735231963686, 'T': 1735231963638, 's': 'STRKUSDT', 'U': 6249657854848, 'u': 6249657859177, 'pu': 6249657849970, 'b': [['0.3760000', '497.1']], 'a': []}
2024-12-26 18:52:44,056 - Нет валидных ордеров после обработки. Исходные данные: {'e': 'depthUpdate', 'E': 1735231964816, 'T': 1735231964715, 's': 'STRKUSDT', 'U': 6249657977833, 'u': 6249657977854, 'pu': 6249657974197, 'b': [['0.4689000', '36156.2'], ['0.4695000', '32153.0']], 'a': []}
2024-12-26 18:52:44,306 - Нет валидных ордеров после обработки. Исходные данные: {'e': 'depthUpdate', 'E': 1735231965065, 'T': 1735231964964, 's': 'STRKUSDT', 'U': 6249657987355, 'u': 6249657987355, 'pu': 6249657981757, 'b': [], 'a': [['0.4723000', '13559.2']]}
2024-12-26 18:52:44,512 - Нет валидных ордеров после обработки. Исходные данные: {'e': 'depthUpdate', 'E': 1735231965272, 'T': 1735231965265, 's': 'STRKUSDT', 'U': 6249658001887, 'u': 6249658005362, 'pu': 6249658001054, 'b': [['0.3761000', '0.0'], ['0.4678000', '28481.7'], ['0.4692000', '51063.1'], ['0.4694000', '27583.2']], 'a': []}
2024-12-26 18:52:44,626 - Нет валидных ордеров после обработки. Исходные данные: {'e': 'depthUpdate', 'E': 1735231965385, 'T': 1735231965287, 's': 'STRKUSDT', 'U': 6249658006952, 'u': 6249658007126, 'pu': 6249658005362, 'b': [['0.4682000', '18728.4'], ['0.4700000', '5086.8']], 'a': []}
2024-12-26 18:52:45,056 - Нет валидных ордеров после обработки. Исходные данные: {'e': 'depthUpdate', 'E': 1735231965815, 'T': 1735231965715, 's': 'STRKUSDT', 'U': 6249658042066, 'u': 6249658042152, 'pu': 6249658039848, 'b': [], 'a': [['0.4706000', '33548.6'], ['0.4708000', '42100.1']]}
2024-12-26 18:52:45,563 - Нет валидных ордеров после обработки. Исходные данные: {'e': 'depthUpdate', 'E': 1735231966315, 'T': 1735231966251, 's': 'STRKUSDT', 'U': 6249658066427, 'u': 6249658068365, 'pu': 6249658063527, 'b': [['0.3761000', '0.0'], ['0.4697000', '15255.2'], ['0.4700000', '5468.4']], 'a': []}
2024-12-26 18:52:45,689 - Нет валидных ордеров после обработки. Исходные данные: {'e': 'depthUpdate', 'E': 1735231966444, 'T': 1735231966345, 's': 'STRKUSDT', 'U': 6249658072345, 'u': 6249658072396, 'pu': 6249658068365, 'b': [], 'a': [['0.4705000', '28851.4'], ['0.4710000', '31667.8']]}
2024-12-26 18:52:45,908 - Нет валидных ордеров после обработки. Исходные данные: {'e': 'depthUpdate', 'E': 1735231966668, 'T': 1735231966620, 's': 'STRKUSDT', 'U': 6249658093626, 'u': 6249658097396, 'pu': 6249658091516, 'b': [['0.4693000', '32843.1'], ['0.4694000', '47365.6'], ['0.4695000', '26605.5'], ['0.4699000', '21014.1'], ['0.4700000', '479.5']], 'a': []}
2024-12-26 18:52:46,029 - Нет валидных ордеров после обработки. Исходные данные: {'e': 'depthUpdate', 'E': 1735231966788, 'T': 1735231966749, 's': 'STRKUSDT', 'U': 6249658100585, 'u': 6249658102933, 'pu': 6249658097396, 'b': [['0.4687000', '45377.8'], ['0.4697000', '13381.5'], ['0.4698000', '23860.1'], ['0.4699000', '19631.1']], 'a': []}
2024-12-26 18:52:46,414 - Нет валидных ордеров после обработки. Исходные данные: {'e': 'depthUpdate', 'E': 1735231967173, 'T': 1735231967151, 's': 'STRKUSDT', 'U': 6249658116493, 'u': 6249658123397, 'pu': 6249658104599, 'b': [['0.3761000', '0.0'], ['0.4693000', '30180.2'], ['0.4694000', '44090.3'], ['0.4695000', '26064.9'], ['0.4696000', '34314.0'], ['0.4697000', '16654.8'], ['0.4698000', '24400.3']], 'a': []}
2024-12-26 18:52:46,624 - Нет валидных ордеров после обработки. Исходные данные: {'e': 'depthUpdate', 'E': 1735231967382, 'T': 1735231967287, 's': 'STRKUSDT', 'U': 6249658129558, 'u': 6249658129920, 'pu': 6249658123397, 'b': [['0.4687000', '43710.8'], ['0.4697000', '18170.4'], ['0.4698000', '24600.3']], 'a': []}
2024-12-26 18:52:46,830 - Нет валидных ордеров после обработки. Исходные данные: {'e': 'depthUpdate', 'E': 1735231967589, 'T': 1735231967587, 's': 'STRKUSDT', 'U': 6249658139154, 'u': 6249658145585, 'pu': 6249658129920, 'b': [['0.4687000', '45415.5'], ['0.4693000', '31246.4'], ['0.4694000', '43024.3'], ['0.4695000', '25852.2'], ['0.4697000', '16654.8'], ['0.4698000', '24400.3']], 'a': []}
2024-12-26 18:52:46,980 - Нет валидных ордеров после обработки. Исходные данные: {'e': 'depthUpdate', 'E': 1735231967740, 'T': 1735231967694, 's': 'STRKUSDT', 'U': 6249658148980, 'u': 6249658154980, 'pu': 6249658145585, 'b': [['0.3761000', '0.0']], 'a': [['0.4701000', '15239.6']]}
2024-12-26 18:52:47,323 - Нет валидных ордеров после обработки. Исходные данные: {'e': 'depthUpdate', 'E': 1735231968082, 'T': 1735231967981, 's': 'STRKUSDT', 'U': 6249658176294, 'u': 6249658176294, 'pu': 6249658165971, 'b': [['0.4662000', '12865.6'], ['0.4684000', '49981.3']], 'a': []}
2024-12-26 18:52:47,487 - Нет валидных ордеров после обработки. Исходные данные: {'e': 'depthUpdate', 'E': 1735231968246, 'T': 1735231968197, 's': 'STRKUSDT', 'U': 6249658184601, 'u': 6249658187182, 'pu': 6249658176294, 'b': [['0.3761000', '0.0']], 'a': [['0.4713000', '50722.0']]}
2024-12-26 18:52:47,930 - Нет валидных ордеров после обработки. Исходные данные: {'e': 'depthUpdate', 'E': 1735231968689, 'T': 1735231968644, 's': 'STRKUSDT', 'U': 6249658203135, 'u': 6249658205646, 'pu': 6249658187182, 'b': [], 'a': [['0.4707000', '37966.1'], ['0.4713000', '51427.8']]}
2024-12-26 18:52:48,036 - Нет валидных ордеров после обработки. Исходные данные: {'e': 'depthUpdate', 'E': 1735231968795, 'T': 1735231968779, 's': 'STRKUSDT', 'U': 6249658207426, 'u': 6249658211960, 'pu': 6249658205646, 'b': [['0.3761000', '0.0']], 'a': []}
2024-12-26 18:52:48,684 - Нет валидных ордеров после обработки. Исходные данные: {'e': 'depthUpdate', 'E': 1735231969443, 'T': 1735231969407, 's': 'STRKUSDT', 'U': 6249658252279, 'u': 6249658254847, 'pu': 6249658250289, 'b': [['0.4687000', '45368.0'], ['0.4697000', '17838.4'], ['0.4700000', '604.0']], 'a': []}
2024-12-26 18:52:48,881 - Нет валидных ордеров после обработки. Исходные данные: {'e': 'depthUpdate', 'E': 1735231969640, 'T': 1735231969587, 's': 'STRKUSDT', 'U': 6249658259948, 'u': 6249658262422, 'pu': 6249658254847, 'b': [['0.4687000', '43710.8'], ['0.4696000', '33914.0'], ['0.4697000', '19709.1'], ['0.4698000', '24600.3']], 'a': []}
2024-12-26 18:52:49,186 - Нет валидных ордеров после обработки. Исходные данные: {'e': 'depthUpdate', 'E': 1735231969945, 'T': 1735231969843, 's': 'STRKUSDT', 'U': 6249658274465, 'u': 6249658274465, 'pu': 6249658271492, 'b': [['0.3761000', '0.0']], 'a': []}
2024-12-26 18:52:49,304 - Нет валидных ордеров после обработки. Исходные данные: {'e': 'depthUpdate', 'E': 1735231970064, 'T': 1735231969962, 's': 'STRKUSDT', 'U': 6249658279116, 'u': 6249658279116, 'pu': 6249658274465, 'b': [], 'a': [['0.4904000', '9991.6']]}
2024-12-26 18:52:49,407 - Нет валидных ордеров после обработки. Исходные данные: {'e': 'depthUpdate', 'E': 1735231970166, 'T': 1735231970122, 's': 'STRKUSDT', 'U': 6249658284661, 'u': 6249658290524, 'pu': 6249658279116, 'b': [['0.4696000', '33914.0'], ['0.4697000', '19709.1'], ['0.4700000', '614.8']], 'a': []}
2024-12-26 18:52:50,780 - Нет валидных ордеров после обработки. Исходные данные: {'e': 'depthUpdate', 'E': 1735231971539, 'T': 1735231971507, 's': 'STRKUSDT', 'U': 6249658365898, 'u': 6249658368167, 'pu': 6249658362526, 'b': [['0.4695000', '21364.5'], ['0.4696000', '34739.4']], 'a': []}
2024-12-26 18:52:50,929 - Нет валидных ордеров после обработки. Исходные данные: {'e': 'depthUpdate', 'E': 1735231971688, 'T': 1735231971587, 's': 'STRKUSDT', 'U': 6249658374873, 'u': 6249658374895, 'pu': 6249658368167, 'b': [['0.4688000', '28245.1'], ['0.4698000', '26365.3']], 'a': []}
2024-12-26 18:52:51,243 - Нет валидных ордеров после обработки. Исходные данные: {'e': 'depthUpdate', 'E': 1735231972002, 'T': 1735231971975, 's': 'STRKUSDT', 'U': 6249658392465, 'u': 6249658398071, 'pu': 6249658374895, 'b': [['0.3760000', '497.1']], 'a': []}
2024-12-26 18:52:51,419 - Нет валидных ордеров после обработки. Исходные данные: {'e': 'depthUpdate', 'E': 1735231972173, 'T': 1735231972124, 's': 'STRKUSDT', 'U': 6249658403759, 'u': 6249658408469, 'pu': 6249658398071, 'b': [['0.4695000', '25788.9'], ['0.4696000', '33589.7'], ['0.4697000', '16776.1'], ['0.4698000', '25825.1']], 'a': []}
2024-12-26 18:52:51,630 - Нет валидных ордеров после обработки. Исходные данные: {'e': 'depthUpdate', 'E': 1735231972389, 'T': 1735231972287, 's': 'STRKUSDT', 'U': 6249658416460, 'u': 6249658416462, 'pu': 6249658408469, 'b': [['0.4688000', '29938.7'], ['0.4698000', '24072.9']], 'a': []}
2024-12-26 18:52:51,786 - Нет валидных ордеров после обработки. Исходные данные: {'e': 'depthUpdate', 'E': 1735231972546, 'T': 1735231972500, 's': 'STRKUSDT', 'U': 6249658424525, 'u': 6249658427149, 'pu': 6249658416462, 'b': [['0.3760000', '497.1']], 'a': []}
2024-12-26 18:52:52,317 - Нет валидных ордеров после обработки. Исходные данные: {'e': 'depthUpdate', 'E': 1735231973076, 'T': 1735231973025, 's': 'STRKUSDT', 'U': 6249658443354, 'u': 6249658445771, 'pu': 6249658427149, 'b': [['0.3760000', '497.1']], 'a': []}
2024-12-26 18:52:53,652 - Нет валидных ордеров после обработки. Исходные данные: {'e': 'depthUpdate', 'E': 1735231974411, 'T': 1735231974347, 's': 'STRKUSDT', 'U': 6249658654154, 'u': 6249658655916, 'pu': 6249658648280, 'b': [['0.4472000', '0.0'], ['0.4698000', '18051.6']], 'a': []}
2024-12-26 18:52:54,451 - Нет валидных ордеров после обработки. Исходные данные: {'e': 'depthUpdate', 'E': 1735231975210, 'T': 1735231975113, 's': 'STRKUSDT', 'U': 6249658829267, 'u': 6249658829955, 'pu': 6249658828809, 'b': [['0.4695000', '22855.8'], ['0.4696000', '14749.2']], 'a': []}
2024-12-26 18:52:55,669 - Нет валидных ордеров после обработки. Исходные данные: {'e': 'depthUpdate', 'E': 1735231976428, 'T': 1735231976327, 's': 'STRKUSDT', 'U': 6249659044159, 'u': 6249659044159, 'pu': 6249659004960, 'b': [['0.4691000', '74359.9'], ['0.4693000', '25505.3']], 'a': []}
2024-12-26 18:52:55,802 - Нет валидных ордеров после обработки. Исходные данные: {'e': 'depthUpdate', 'E': 1735231976553, 'T': 1735231976501, 's': 'STRKUSDT', 'U': 6249659079072, 'u': 6249659084543, 'pu': 6249659044159, 'b': [['0.3758000', '1412.5'], ['0.4685000', '12593.4'], ['0.4687000', '46109.2'], ['0.4689000', '22812.7']], 'a': []}
2024-12-26 18:52:56,868 - Нет валидных ордеров после обработки. Исходные данные: {'e': 'depthUpdate', 'E': 1735231977627, 'T': 1735231977547, 's': 'STRKUSDT', 'U': 6249659332582, 'u': 6249659334234, 'pu': 6249659328181, 'b': [['0.4683000', '82590.8'], ['0.4685000', '15140.6'], ['0.4693000', '24644.0'], ['0.4694000', '12138.9']], 'a': []}
2024-12-26 18:52:57,098 - Нет валидных ордеров после обработки. Исходные данные: {'e': 'depthUpdate', 'E': 1735231977858, 'T': 1735231977839, 's': 'STRKUSDT', 'U': 6249659349002, 'u': 6249659353981, 'pu': 6249659347792, 'b': [['0.4573000', '12736.4'], ['0.4687000', '49110.6'], ['0.4688000', '41482.4'], ['0.4689000', '47117.4'], ['0.4690000', '49466.2'], ['0.4691000', '14197.6'], ['0.4692000', '22547.9'], ['0.4693000', '19325.9']], 'a': []}
2024-12-26 18:52:57,205 - Нет валидных ордеров после обработки. Исходные данные: {'e': 'depthUpdate', 'E': 1735231977964, 'T': 1735231977926, 's': 'STRKUSDT', 'U': 6249659356040, 'u': 6249659363887, 'pu': 6249659353981, 'b': [['0.3757000', '159.7'], ['0.4692000', '22103.2']], 'a': []}
2024-12-26 18:52:57,328 - Нет валидных ордеров после обработки. Исходные данные: {'e': 'depthUpdate', 'E': 1735231978079, 'T': 1735231978026, 's': 'STRKUSDT', 'U': 6249659368160, 'u': 6249659372660, 'pu': 6249659363887, 'b': [['0.3757000', '0.0']], 'a': [['0.4696000', '13604.0'], ['0.4700000', '39282.9'], ['0.5157000', '23.4']]}
2024-12-26 18:52:57,625 - Нет валидных ордеров после обработки. Исходные данные: {'e': 'depthUpdate', 'E': 1735231978384, 'T': 1735231978284, 's': 'STRKUSDT', 'U': 6249659392519, 'u': 6249659392569, 'pu': 6249659372660, 'b': [['0.4688000', '41696.3'], ['0.4694000', '10859.0']], 'a': []}
2024-12-26 18:52:57,843 - Нет валидных ордеров после обработки. Исходные данные: {'e': 'depthUpdate', 'E': 1735231978602, 'T': 1735231978592, 's': 'STRKUSDT', 'U': 6249659404269, 'u': 6249659408741, 'pu': 6249659392569, 'b': [['0.3757000', '0.0']], 'a': [['0.4817000', '20125.3']]}
2024-12-26 18:52:58,450 - Нет валидных ордеров после обработки. Исходные данные: {'e': 'depthUpdate', 'E': 1735231979209, 'T': 1735231979195, 's': 'STRKUSDT', 'U': 6249659453798, 'u': 6249659457925, 'pu': 6249659453047, 'b': [['0.4546000', '16180.4'], ['0.4685000', '15163.1']], 'a': []}
2024-12-26 18:52:58,843 - Нет валидных ордеров после обработки. Исходные данные: {'e': 'depthUpdate', 'E': 1735231979601, 'T': 1735231979584, 's': 'STRKUSDT', 'U': 6249659471170, 'u': 6249659474653, 'pu': 6249659457925, 'b': [['0.3757000', '0.0']], 'a': []}
2024-12-26 18:53:01,447 - Нет валидных ордеров после обработки. Исходные данные: {'e': 'depthUpdate', 'E': 1735231982207, 'T': 1735231982129, 's': 'STRKUSDT', 'U': 6249659792464, 'u': 6249659798490, 'pu': 6249659791059, 'b': [['0.4691000', '19989.6'], ['0.4692000', '27520.5'], ['0.4693000', '27169.7']], 'a': []}
2024-12-26 18:53:03,540 - Нет валидных ордеров после обработки. Исходные данные: {'e': 'depthUpdate', 'E': 1735231984299, 'T': 1735231984198, 's': 'STRKUSDT', 'U': 6249660100860, 'u': 6249660100860, 'pu': 6249660093816, 'b': [['0.4560000', '17502.1']], 'a': []}
2024-12-26 18:53:03,817 - Нет валидных ордеров после обработки. Исходные данные: {'e': 'depthUpdate', 'E': 1735231984577, 'T': 1735231984554, 's': 'STRKUSDT', 'U': 6249660120401, 'u': 6249660124629, 'pu': 6249660100860, 'b': [['0.3758000', '1572.1'], ['0.4568000', '4915.7'], ['0.4692000', '37759.5'], ['0.4697000', '5265.6']], 'a': []}
2024-12-26 18:53:03,947 - Нет валидных ордеров после обработки. Исходные данные: {'e': 'depthUpdate', 'E': 1735231984705, 'T': 1735231984604, 's': 'STRKUSDT', 'U': 6249660126499, 'u': 6249660126499, 'pu': 6249660124629, 'b': [['0.3758000', '1412.5']], 'a': []}
2024-12-26 18:53:04,087 - Нет валидных ордеров после обработки. Исходные данные: {'e': 'depthUpdate', 'E': 1735231984845, 'T': 1735231984745, 's': 'STRKUSDT', 'U': 6249660133064, 'u': 6249660133114, 'pu': 6249660126499, 'b': [['0.4583000', '23405.9'], ['0.4687000', '47966.5']], 'a': []}
2024-12-26 18:53:04,729 - Нет валидных ордеров после обработки. Исходные данные: {'e': 'depthUpdate', 'E': 1735231985488, 'T': 1735231985486, 's': 'STRKUSDT', 'U': 6249660177793, 'u': 6249660183189, 'pu': 6249660174892, 'b': [], 'a': [['0.4698000', '1551.7'], ['0.4700000', '26745.3'], ['0.4710000', '35248.8']]}
2024-12-26 18:53:05,048 - Нет валидных ордеров после обработки. Исходные данные: {'e': 'depthUpdate', 'E': 1735231985808, 'T': 1735231985717, 's': 'STRKUSDT', 'U': 6249660193758, 'u': 6249660194230, 'pu': 6249660192958, 'b': [['0.4638000', '19831.5'], ['0.4687000', '51380.5']], 'a': []}
2024-12-26 18:53:05,939 - Нет валидных ордеров после обработки. Исходные данные: {'e': 'depthUpdate', 'E': 1735231986699, 'T': 1735231986690, 's': 'STRKUSDT', 'U': 6249660276827, 'u': 6249660283428, 'pu': 6249660270600, 'b': [], 'a': [['0.4834000', '9928.5'], ['0.5021000', '87.3']]}
2024-12-26 18:53:06,042 - Нет валидных ордеров после обработки. Исходные данные: {'e': 'depthUpdate', 'E': 1735231986801, 'T': 1735231986774, 's': 'STRKUSDT', 'U': 6249660283801, 'u': 6249660288631, 'pu': 6249660283428, 'b': [['0.3758000', '1412.5'], ['0.4558000', '2457.4']], 'a': []}
2024-12-26 18:53:06,720 - Нет валидных ордеров после обработки. Исходные данные: {'e': 'depthUpdate', 'E': 1735231987480, 'T': 1735231987381, 's': 'STRKUSDT', 'U': 6249660341614, 'u': 6249660341670, 'pu': 6249660336940, 'b': [['0.4697000', '222.0']], 'a': []}
2024-12-26 18:53:07,168 - Нет валидных ордеров после обработки. Исходные данные: {'e': 'depthUpdate', 'E': 1735231987926, 'T': 1735231987825, 's': 'STRKUSDT', 'U': 6249660371232, 'u': 6249660371232, 'pu': 6249660367466, 'b': [['0.3758000', '1412.5']], 'a': []}
2024-12-26 18:53:07,810 - Нет валидных ордеров после обработки. Исходные данные: {'e': 'depthUpdate', 'E': 1735231988566, 'T': 1735231988487, 's': 'STRKUSDT', 'U': 6249660430264, 'u': 6249660432345, 'pu': 6249660424807, 'b': [], 'a': [['0.4698000', '4338.1'], ['0.4699000', '24569.1']]}
2024-12-26 18:53:08,530 - Нет валидных ордеров после обработки. Исходные данные: {'e': 'depthUpdate', 'E': 1735231989290, 'T': 1735231989189, 's': 'STRKUSDT', 'U': 6249660480304, 'u': 6249660480304, 'pu': 6249660476851, 'b': [['0.4692000', '28704.4']], 'a': []}
2024-12-26 18:53:08,678 - Нет валидных ордеров после обработки. Исходные данные: {'e': 'depthUpdate', 'E': 1735231989436, 'T': 1735231989400, 's': 'STRKUSDT', 'U': 6249660490917, 'u': 6249660493906, 'pu': 6249660480304, 'b': [['0.3758000', '1412.5']], 'a': []}
2024-12-26 18:53:09,204 - Нет валидных ордеров после обработки. Исходные данные: {'e': 'depthUpdate', 'E': 1735231989963, 'T': 1735231989914, 's': 'STRKUSDT', 'U': 6249660510398, 'u': 6249660512625, 'pu': 6249660493906, 'b': [['0.3758000', '1412.5']], 'a': []}
2024-12-26 18:53:09,318 - Нет валидных ордеров после обработки. Исходные данные: {'e': 'depthUpdate', 'E': 1735231990073, 'T': 1735231990070, 's': 'STRKUSDT', 'U': 6249660514605, 'u': 6249660522060, 'pu': 6249660512625, 'b': [], 'a': [['0.4698000', '4120.7'], ['0.4699000', '24569.1'], ['0.4703000', '36692.8'], ['0.4704000', '30580.3']]}
2024-12-26 18:53:09,419 - Нет валидных ордеров после обработки. Исходные данные: {'e': 'depthUpdate', 'E': 1735231990179, 'T': 1735231990124, 's': 'STRKUSDT', 'U': 6249660523079, 'u': 6249660527967, 'pu': 6249660522060, 'b': [['0.4693000', '28062.5'], ['0.4694000', '28892.5'], ['0.4695000', '30259.1']], 'a': []}
2024-12-26 18:53:09,826 - Нет валидных ордеров после обработки. Исходные данные: {'e': 'depthUpdate', 'E': 1735231990574, 'T': 1735231990498, 's': 'STRKUSDT', 'U': 6249660584749, 'u': 6249660588518, 'pu': 6249660570991, 'b': [['0.3758000', '1412.5'], ['0.4179000', '354.4'], ['0.4690000', '66854.6'], ['0.4691000', '33639.2']], 'a': []}
2024-12-26 18:53:09,954 - Нет валидных ордеров после обработки. Исходные данные: {'e': 'depthUpdate', 'E': 1735231990711, 'T': 1735231990610, 's': 'STRKUSDT', 'U': 6249660597158, 'u': 6249660597158, 'pu': 6249660588518, 'b': [['0.4690000', '67921.4'], ['0.4691000', '32572.4']], 'a': []}
2024-12-26 18:53:10,055 - Нет валидных ордеров после обработки. Исходные данные: {'e': 'depthUpdate', 'E': 1735231990814, 'T': 1735231990713, 's': 'STRKUSDT', 'U': 6249660602510, 'u': 6249660602632, 'pu': 6249660597158, 'b': [], 'a': [['0.4700000', '28595.2'], ['0.4701000', '19958.4']]}
2024-12-26 18:53:10,694 - Нет валидных ордеров после обработки. Исходные данные: {'e': 'depthUpdate', 'E': 1735231991453, 'T': 1735231991353, 's': 'STRKUSDT', 'U': 6249660646667, 'u': 6249660646696, 'pu': 6249660627844, 'b': [], 'a': [['0.4700000', '28595.2'], ['0.4701000', '19958.4']]}
2024-12-26 18:53:10,955 - Нет валидных ордеров после обработки. Исходные данные: {'e': 'depthUpdate', 'E': 1735231991709, 'T': 1735231991611, 's': 'STRKUSDT', 'U': 6249660666141, 'u': 6249660667809, 'pu': 6249660657087, 'b': [], 'a': [['0.4698000', '5516.7']]}
2024-12-26 18:53:11,277 - Нет валидных ордеров после обработки. Исходные данные: {'e': 'depthUpdate', 'E': 1735231992035, 'T': 1735231992014, 's': 'STRKUSDT', 'U': 6249660726750, 'u': 6249660732396, 'pu': 6249660716171, 'b': [['0.3758000', '1572.1'], ['0.4177000', '752.3'], ['0.4697000', '331.9']], 'a': []}
2024-12-26 18:53:11,683 - Нет валидных ордеров после обработки. Исходные данные: {'e': 'depthUpdate', 'E': 1735231992442, 'T': 1735231992340, 's': 'STRKUSDT', 'U': 6249660780844, 'u': 6249660780844, 'pu': 6249660776865, 'b': [['0.4697000', '8062.9']], 'a': []}
2024-12-26 18:53:14,242 - Нет валидных ордеров после обработки. Исходные данные: {'e': 'depthUpdate', 'E': 1735231995002, 'T': 1735231994974, 's': 'STRKUSDT', 'U': 6249660991843, 'u': 6249660995476, 'pu': 6249660965898, 'b': [['0.3758000', '1412.5']], 'a': []}
2024-12-26 18:53:14,868 - Нет валидных ордеров после обработки. Исходные данные: {'e': 'depthUpdate', 'E': 1735231995627, 'T': 1735231995526, 's': 'STRKUSDT', 'U': 6249661084613, 'u': 6249661084613, 'pu': 6249661081944, 'b': [], 'a': [['0.4698000', '2999.3']]}
